<?xml version="1.0" ?>
<!-- =================================================================================== -->
<!-- |    This document was autogenerated by xacro from jaka.urdf.xacro                | -->
<!-- |    EDITING THIS FILE BY HAND IS NOT RECOMMENDED                                 | -->
<!-- =================================================================================== -->
<robot name="jakaUr" xmlns:xacro="http://www.ros.org/wiki/xacro">
  <material name="blue">
    <color rgba="0 0 0.8 1"/>
  </material>
  <material name="black">
    <color rgba="0 0 0 1"/>
  </material>
  <material name="white">
    <color rgba="1 1 1 1"/>
  </material>
  <!--############## link ##############-->
  <link name="world"/>
  <link name="bottom_link">
    <!--visual><origin xyz=" 0 0 -0.04"  rpy="0 0 0"/><geometry><box size="1 1 0.02" /></geometry><material name="Brown" /></visual><collision><origin xyz=" 0 0 -0.04"  rpy="0 0 0"/><geometry><box size="1 1 0.02" /></geometry></collision>-->
    <inertial>
      <mass value="5"/>
      <inertia ixx="0.2" ixy="0.0" ixz="0.0" iyy="0.2" iyz="0.0" izz="0.1"/>
    </inertial>
  </link>
  <link name="base_link">
    <visual>
      <!--origin rpy="0 ${pi / 2} 0" xyz="0 0 0.0198"/>-->
      <origin rpy="0 0 0" xyz="0 0 -0.0005"/>
      <geometry>
        <mesh filename="package://jaka_description/meshes/p11.dae"/>
      </geometry>
      <material name="white">
        <color rgba="1 1 1 1"/>
      </material>
    </visual>
    <collision>
      <geometry>
        <mesh filename="package://jaka_description/meshes/p11.dae"/>
      </geometry>
      <origin rpy="0 0 0" xyz="0 0 -0.0005"/>
    </collision>
    <!--inertial><mass value="5"/><inertia ixx="0.2" ixy="0.0" ixz="0.0" iyy="0.2" iyz="0.0" izz="0.1"/></inertial-->
  </link>
  <link name="link_1">
    <visual>
      <geometry>
        <mesh filename="package://jaka_description/meshes/p22.dae"/>
      </geometry>
      <material name="white">
        <color rgba="1 1 1 1"/>
      </material>
      <!--origin rpy=" ${pi/2.0}  0  ${pi/2.0}" xyz="0 0 0"/>-->
      <origin rpy=" 0  0  0" xyz="0 0 0"/>
    </visual>
    <collision>
      <geometry>
        <mesh filename="package://jaka_description/meshes/p22.dae"/>
      </geometry>
      <origin rpy=" 0  0  0" xyz="0 0 0"/>
    </collision>
    <inertial>
      <mass value="8"/>
      <inertia ixx="0.3" ixy="0.0" ixz="0.0" iyy="0.3" iyz="0.0" izz="0.2"/>
    </inertial>
  </link>
  <link name="link_2">
    <visual>
      <geometry>
        <mesh filename="package://jaka_description/meshes/p35.dae"/>
      </geometry>
      <!--origin rpy="${pi/2.0}  ${pi} ${pi/2.0}" xyz="-0.1595 0 -0.115"/>-->
      <material name="white">
        <color rgba="1 1 1 1"/>
      </material>
      <origin rpy="1.57079632679 3.14159265358 1.57079632679" xyz="0 0 0.005 "/>
      <material name="white">
        <color rgba="1 1 1 1"/>
      </material>
    </visual>
    <collision>
      <geometry>
        <mesh filename="package://jaka_description/meshes/p35.dae"/>
      </geometry>
      <origin rpy="1.57079632679 3.14159265358 1.57079632679" xyz="0 0 0.005 "/>
    </collision>
    <inertial>
      <mass value="6"/>
      <inertia ixx="0.25" ixy="0.0" ixz="0.0" iyy="0.25" iyz="0.0" izz="0.15"/>
    </inertial>
  </link>
  <link name="link_3">
    <visual>
      <geometry>
        <mesh filename="package://jaka_description/meshes/p44.dae"/>
      </geometry>
      <material name="white">
        <color rgba="1 1 1 1"/>
      </material>
      <origin rpy="-1.57079632679 0 -1.57079632679" xyz="0.303 0 -0.013"/>
    </visual>
    <collision>
      <geometry>
        <mesh filename="package://jaka_description/meshes/p44.dae"/>
      </geometry>
      <origin rpy="-1.57079632679 0 -1.57079632679" xyz="0.303 0 -0.013"/>
    </collision>
    <inertial>
      <mass value="8"/>
      <inertia ixx="0.3" ixy="0.0" ixz="0.0" iyy="0.3" iyz="0.0" izz="0.2"/>
    </inertial>
  </link>
  <link name="link_4">
    <visual>
      <geometry>
        <mesh filename="package://jaka_description/meshes/p55.dae"/>
      </geometry>
      <origin rpy="1.57079632679 0 1.57079632679" xyz="0.00 0 0.00"/>
      <material name="white">
        <color rgba="1 1 1 1"/>
      </material>
    </visual>
    <collision>
      <geometry>
        <mesh filename="package://jaka_description/meshes/p55.dae"/>
      </geometry>
      <origin rpy="1.57079632679 0 1.57079632679" xyz="0.00 0 0.00"/>
    </collision>
    <inertial>
      <mass value="5"/>
      <inertia ixx="0.2" ixy="0.0" ixz="0.0" iyy="0.2" iyz="0.0" izz="0.15"/>
    </inertial>
  </link>
  <link name="link_5">
    <visual>
      <geometry>
        <mesh filename="package://jaka_description/meshes/p66.dae"/>
      </geometry>
      <origin rpy="3.14159265358 0 -1.57079632679" xyz="0 0 0"/>
      <material name="white">
        <color rgba="1 1 1 1"/>
      </material>
    </visual>
    <collision>
      <geometry>
        <mesh filename="package://jaka_description/meshes/p66.dae"/>
      </geometry>
      <origin rpy="3.14159265358 0 -1.57079632679" xyz="0 0 0"/>
    </collision>
    <inertial>
      <mass value="4"/>
      <inertia ixx="0.1" ixy="0.0" ixz="0.0" iyy="0.1" iyz="0.0" izz="0.07"/>
    </inertial>
  </link>
  <link name="link_6">
    <visual>
      <geometry>
        <mesh filename="package://jaka_description/meshes/p77.dae"/>
      </geometry>
      <origin rpy="0 -1.57079632679  0" xyz="0 0 -0.0335"/>
    </visual>
    <collision>
      <geometry>
        <mesh filename="package://jaka_description/meshes/p77.dae"/>
      </geometry>
      <origin rpy="0 -1.57079632679  0" xyz="0 0 -0.0335"/>
    </collision>
    <inertial>
      <mass value="2"/>
      <inertia ixx="0.07" ixy="0.0" ixz="0.0" iyy="0.07" iyz="0.0" izz="0.04"/>
    </inertial>
  </link>
  <link name="ee_link">
    <collision>
      <geometry>
        <box size="0.01 0.01 0.01"/>
      </geometry>
      <origin rpy="0 0 0" xyz="0.01 0 0"/>
    </collision>
  </link>
  <!--############## joint ##############-->
  <joint name="world_joint" type="fixed">
    <origin rpy="0 0 0" xyz="0 0 0"/>
    <parent link="world"/>
    <child link="base_link"/>
  </joint>
  <joint name="bottom_joint" type="fixed">
    <origin rpy="0 0 0" xyz="0 0 0"/>
    <parent link="base_link"/>
    <child link="bottom_link"/>
  </joint>
  <joint name="joint_1" type="revolute">
    <axis xyz="0 0 1"/>
    <limit effort="1000" lower="-3.14159265358" upper="3.14159265358" velocity="0.5"/>
    <origin rpy="0 0 0" xyz="0 0 0.114"/>
    <parent link="base_link"/>
    <child link="link_1"/>
  </joint>
  <joint name="joint_2" type="revolute">
    <axis xyz="0 0 1"/>
    <limit effort="1000" lower="-1.58" upper="4.71238898" velocity="0.5"/>
    <origin rpy="1.57079632679 0 0" xyz="0 0 0"/>
    <parent link="link_1"/>
    <child link="link_2"/>
  </joint>
  <joint name="joint_3" type="revolute">
    <axis xyz="0 0 1"/>
    <limit effort="1000" lower="-3.14159265358" upper="3.14159265358" velocity="0.5"/>
    <origin rpy="0 0 0" xyz="0.353 0 0"/>
    <parent link="link_2"/>
    <child link="link_3"/>
  </joint>
  <joint name="joint_4" type="revolute">
    <axis xyz="0 0 1"/>
    <limit effort="1000" lower="-3.14159265358" upper="3.14159265358" velocity="0.5"/>
    <origin rpy="0 0 0" xyz="0.303 0 -0.1155"/>
    <parent link="link_3"/>
    <child link="link_4"/>
  </joint>
  <joint name="joint_5" type="revolute">
    <axis xyz="0 0 1"/>
    <limit effort="1000" lower="-3.14159265358" upper="3.14159265358" velocity="0.5"/>
    <origin rpy="1.57079632679 0 0" xyz="0 -0.1025 0"/>
    <parent link="link_4"/>
    <child link="link_5"/>
  </joint>
  <joint name="joint_6" type="revolute">
    <axis xyz="0 0 1"/>
    <limit effort="1000" lower="-3.14159265358" upper="3.14159265358" velocity="0.5"/>
    <origin rpy="-1.57079632679 0 0" xyz="0 0.093 0"/>
    <parent link="link_5"/>
    <child link="link_6"/>
  </joint>
  <joint name="ee_fixed_joint" type="fixed">
    <parent link="link_6"/>
    <child link="ee_link"/>
    <origin rpy="0.0 0.0 0.0" xyz="0.0 0.0 0.0"/>
  </joint>
  <transmission name="joint_1_trans">
    <type>transmission_interface/SimpleTransmission</type>
    <actuator name="$joint_1_motor">
      <mechanicalReduction>1</mechanicalReduction>
    </actuator>
    <joint name="joint_1">
      <hardwareInterface>PositionJointInterface</hardwareInterface>
    </joint>
  </transmission>
  <transmission name="joint_2_trans">
    <type>transmission_interface/SimpleTransmission</type>
    <actuator name="$joint_2_motor">
      <mechanicalReduction>1</mechanicalReduction>
    </actuator>
    <joint name="joint_2">
      <hardwareInterface>PositionJointInterface</hardwareInterface>
    </joint>
  </transmission>
  <transmission name="joint_3_trans">
    <type>transmission_interface/SimpleTransmission</type>
    <actuator name="joint_3_motor">
      <mechanicalReduction>1</mechanicalReduction>
    </actuator>
    <joint name="joint_3">
      <hardwareInterface>PositionJointInterface</hardwareInterface>
    </joint>
  </transmission>
  <transmission name="joint_4_trans">
    <type>transmission_interface/SimpleTransmission</type>
    <actuator name="joint_4_motor">
      <mechanicalReduction>1</mechanicalReduction>
    </actuator>
    <joint name="joint_4">
      <hardwareInterface>PositionJointInterface</hardwareInterface>
    </joint>
  </transmission>
  <transmission name="joint_5_trans">
    <type>transmission_interface/SimpleTransmission</type>
    <actuator name="joint_5_motor">
      <mechanicalReduction>1</mechanicalReduction>
    </actuator>
    <joint name="joint_5">
      <hardwareInterface>PositionJointInterface</hardwareInterface>
    </joint>
  </transmission>
  <transmission name="joint_6_trans">
    <type>transmission_interface/SimpleTransmission</type>
    <actuator name="joint_6_motor">
      <mechanicalReduction>1</mechanicalReduction>
    </actuator>
    <joint name="joint_6">
      <hardwareInterface>PositionJointInterface</hardwareInterface>
    </joint>
  </transmission>
  <!--########### ros_control plugin ###########-->
  <gazebo>
    <plugin filename="libgazebo_ros_control.so" name="gazebo_ros_control">
      <robotNamespace>/jakaUr</robotNamespace>
    </plugin>
  </gazebo>
</robot>

